Workbook

Sheet Compresor
B2: Datos entrada | C2: valores | D2: unidades | N2: Parametros salida | O2: valores | P2: unidades
B3: m | C3: 30 | D3: kg/s | N3: Cp2 | O3: =(C24+C25*O4+C26*O4^2+C27*O4^3+C28*O4^4)*C22 -> 1014.6583 | P3: J/kgK
B4: T01c | C4: 300 | D4: K | N4: T2 | O4: =G21-(K33^2/(2*O3)) -> 365.94818 | P4: K | Q4: =G21/(1+Q6^2*((C19-1)/2)) -> 393.58903
B5: P01c | C5: 101 | D5: Kpa | N5: a2 | O5: =SQRT(C19*C22*O4) -> 383.48872 | P5: m/s | Q5: =SQRT(G21*C19*C22) -> 448.4293
B6: P02c/P01c | C6: 4.5 | N6: M2 | O6: =K33/O5 -> 1.3620025 | Q6: =K33/Q5 -> 1.1647601
B7: M1 | C7: 0.65 | N7: P2 | O7: =C6*C5/(1+((C19-1)/2)*O6^2)^(C20) -> 150.62309 | P7: KPa | Q7: =C6*C5/(1+((C19-1)/2)*Q6^2)^(C20) -> 196.16702
B8: Dshorud | C8: 30 | D8: mm | N8: ρ2 | O8: =O7*1000/O4/C22 -> 1.4338853 | P8: kg/m3 | Q8: =Q7/(C22*Q4)*1000 -> 1.7363028
B9: z | C9: 20 | N9: D2 | O9: =60*1000*K27/PI()/G16 -> 1255.064 | P9: mm | Q9: =O9 -> 1255.064
B10: Wr2/U2 | C10: 0.64 | N10: b2 | O10: =C3/K31/O8/2/PI()/O9*2*(1000^2) -> 17.5303 | P10: mm | Q10: =C3/K31/Q8/2/PI()/Q9*2*(1000^2) -> 14.476991
B11: α1 | C11: 0 | D11: °
N12: Limitaciones | O12: valor | P12: unidad
B13: Parametros absolutos entrada | C13: Valor | D13: unidades | N13: w | O13: =G16*2*PI()/60 -> 753.67809 | P13: rad/s
B14: T1c | C14: =C4/(1+(C19-1)/2*C7^2) -> 276.62517 | D14: K | N14: U_tip | O14: =K23/2*O13/1000 -> 161.27678 | P14: m/s
B15: P1c | C15: =C5*(C14/C4)^(C19/(C19-1)) -> 76.035766 | D15: Kpa | F15: Datos figura 2 | G15: valores | H15: unidades | J15: Datos figura 2 | K15: Valor | L15: ηtotal obtenido | N15: w1tip | O15: =O24 -> 270.14516 | P15: m/s
B16: ρ1c | C16: =C15/(C14*C22)*1000 -> 0.95756591 | D16: kg/m3 | F16: N | G16: =O21 -> 7197.0956 | H16: rpm | J16: ηpc | K16: 0.84 | N16: beta1_tip | O16: =ATAN(O14/O15)*180/PI() -> 30.83722 | P16: °
F17: ηtotal | G17: =(C6^(C21)-1)/(C6^(C21/K16)-1) -> 0.80374013 | J17: Ns propuesto | K17: 0.74 | N17: a1 | O17: =SQRT(C14*C19*C22) -> 333.41769 | P17: m/s
B18: DATOS AIRE | C18: valor | D18: unidades | J18: Ns obtenido | K18: =2*PI()/60*G16*SQRT(G20)/G25^(3/4) -> 0.43816427 | N18: M1_r | O18: =O15/O17 -> 0.81023044
B19: γ | C19: 1.4 | F19: Calculo de potenica | G19: valores | H19: unidades
B20: γ/(γ-1) | C20: =C21^(-1) -> 3.5 | F20: Q | G20: =C3/C16 -> 31.329436 | H20: m3/s | J20: Diametro ojo | K20: valores | L20: unidades | N20: N | O20: =O21*2*PI()/60 -> 753.67809 | P20: rad/s
B21: (γ-1)/γ | C21: =(C19-1)/C19 -> 0.28571429 | F21: T02c | G21: =C4*C6^(C21/K16) -> 500.38281 | H21: K | J21: Cx | K21: =C7*SQRT(C22*C19*C14) -> 216.7215 | L21: m/s | N21: N | O21: {=K17*(G24*(G21-C4)^{0.75})/(C3/C16)^{0.5}} -> 7197.0956 | P21: rpm
B22: R | C22: 287.05 | D22: J/kgK | F22: Cp10 | G22: =(C24+C25*C4+C26*C4^2+C27*C4^3+C28*C4^4)*C22 -> 1008.6522 | H22: J/kgK | J22: AE | K22: =C3/(C16*K21)*1000^2 -> 144560.81 | L22: mm^2 | N22: D0_ojo | O22: {=SQRT((4*C3/(PI()*C16*K21))-((C8/1000)^{2}))} -> 0.4279726 | P22: m
B23: Cp/R para T<1000 | D23: J/(kg K) | F23: Cp20 | G23: =(C24+C25*G21+C26*G21^2+C27*G21^3+C28*G21^4)*C22 -> 1035.6095 | H23: J/kgK | J23: Dtip | K23: =2*SQRT(K22/PI()-(C8/2)^2) -> 427.9726 | L23: mm | N23: U_tip | O23: =O21*2*PI()/60*O22/2 -> 161.27678 | P23: m/s
B24: a0 | C24: 3.5839058 | F24: CpM | G24: =(G22+G23)/2 -> 1022.1308 | H24: J/kgK | N24: w1 | O24: {=SQRT(O23^{2}+K21^{2})} -> 270.14516 | P24: m/s
B25: a1 | C25: -0.000750907 | F25: Δh0 | G25: =G24*(G21-C4) -> 204817.45 | H25: m2/s2 | J25: Velocidades salida | K25: valor | L25: unidades | N25: beta1 | O25: =ATAN(O23/K21)*180/PI() -> 36.655371 | P25: °
B26: a2 | C26: 1.87026e-06 | F26: Pot | G26: =C3*G25/1000 -> 6144.5235 | H26: kW | J26: β2 | K26: =ATAN((1-G30)/C10)*180/PI() -> 8.8806592 | L26: ° | N26: Ma_1_r | O26: =O24/SQRT(C19*C22*C14) -> 0.81023044
B27: a3 | C27: -3.91028e-10 | J27: U2 | K27: =G31*G29 -> 472.95713 | L27: m/s | N27: U2 | O27: =SQRT(G24*(G21-C4)/G30) -> 477.04816 | P27: m/s
B28: a4 | C28: -3.14052e-13 | F28: Indice Mach/U2 | G28: Valor | H28: unidades | J28: wr2 | K28: =C10*K27 -> 302.69256 | L28: m/s | N28: D2 | O28: =2*O27/(O21*2*PI()/60) -> 1.2659202 | P28: m
B29: Cp/R para T>1000 | F29: a01 | G29: =SQRT(C22*C19*C4) -> 347.21895 | H29: m/s | J29: wΘ2 | K29: =K28*TAN(PI()/180*K26) -> 47.295713 | L29: m/s | N29: Indice de Mach:2 | O29: =O27/SQRT(C19*C22*C4) -> 1.3739116
B30: a0 | C30: 3.0483823 | F30: ξ | G30: =1-2/C9 -> 0.9 | J30: w2 | K30: =K28/COS(K26*PI()/180) -> 306.36526 | L30: m/s | N30: c_theta_2 | O30: =G30*O27 -> 429.34334 | P30: m/s
B31: a1 | C31: 0.001324338 | F31: πM | G31: =SQRT((G21-C4)/(C4*(C19-1)*G30)) -> 1.3621294 | J31: Cr2 | K31: =K28 -> 302.69256 | L31: m/s | N31: w2 | O31: =C10*O27 -> 305.31082 | P31: m/s
B32: a2 | C32: -4.64808e-07 | J32: CΘ2 | K32: =K27-K29 -> 425.66141 | L32: m/s | N32: cr2 | O32: =O31 -> 305.31082 | P32: m/s
B33: a3 | C33: 7.32631e-11 | J33: C2 | K33: =SQRT(K31^2+K32^2) -> 522.31258 | L33: m/s | N33: Beta2 | O33: =ATAN((O27-O30)/O31)*(180/PI()) -> 8.8806592 | P33: °
B34: a4 | C34: -4.15928e-15 | G34: =SQRT(G24*(G21-C4)/G30)/G29 -> 1.3739116 | J34: α2 | K34: =ATAN(K32/K31)*180/PI() -> 54.582945 | L34: ° | N34: alpha2 | O34: =ACOS(O32/O35)*180/PI() -> 54.582945 | P34: °
N35: c2 | O35: {=SQRT(O32^{2}+O30^{2})} -> 526.83053 | P35: m/s
J37: Difusor
J38: alfa2 | K38: =K34 -> 54.582945 | N38: Coeficiente de Flujo | O38: valor
J39: alfa* | K39: =ATAN(TAN(K34*PI()/180)*((2/(C19+1))*(1+O6^(2)*((C19-1)/2))^(1/(C19-1))))*180/PI() -> 68.807744 | L39: ° | N39: fi | O39: =C3/(O8*(O9)^2*K27)*1000^2*2 -> 0.056167269
J40: r* | K40: =(O9/2)*(SIN(K34*PI()/180)/SIN(K39*PI()/180))*O6*(((C19+1)/2)/(1+((C19-1)/2)*O6*O6))^(0.5) -> 698.9214 | L40: mm
J41: r2 | K41: =O9/2 -> 627.53201 | L41: mm
J42: M3 | K42: 0.8
...

Sheet Camara_Combustion
A2: Datos de entrada | B2: valor | C2: unidades | E2: Para menor a mil
A3: Combustible | B3: PETROLEO DE AVIACION | E3: DeltaTestimado | F3: valor | G3: unidad
A4: Poder calorifico Inferior | B4: 43500 | C4: KJ/KG | E4: cp_inicio | F4: =(B17+$B$11*B18+B19*$B$11^2+B20*$B$11^3+B21*$B$11^4)*B15 -> 1.0354291 | G4: KJ/KG K
A5: Rendimiento de combustión | B5: 0.6 | C5: % | E5: cp_final | F5: =(B17+B9*B18+B19*B9^2+B20*B9^3+B21*B9^4)*B15 -> 1.1474773 | G5: KJ/KG K
A6: Relacion Aire-Combustible | B6: 31 | C6: 31:1 | E6: cp_medio | F6: =(F4+F5)/2 -> 1.0914532 | G6: KJ/KG K
A7: cp_medio | B7: =(F6*F7+F12*F13)/(F7+F13) -> 1.1149613 | C7: KJ/KG K | E7: rango de T | F7: =1000-B11 -> 499.61719 | G7: K
A8: Delta Testimado | B8: =B14-1000 -> 255.50812 | C8: K | E8: Para mayor a mil
A9: T0_limite superior | B9: 1000 | C9: K | E9: DeltaTestimado | F9: valor | G9: unidad
E10: cp_inicio | F10: =(B23+B9*B24+B25*B9^2+B26*B9^3+B27*B9^4)*B15 -> 1.1414036 | G10: KJ/KG K
A11: T0 inicio | B11: =Compresor!K45 -> 500.38281 | C11: K | E11: cp_final | F11: =(B23+(B8+B9)*B24+B25*(B8+B9)^2+B26*(B8+B9)^3+B27*(B8+B9)^4)*B15 -> 1.1804538 | G11: KJ/KG K
A12: Delta_T | B12: =B5*B4/(B6*B7) -> 755.12531 | C12: K | E12: cp_medio | F12: =(F10+F11)/2 -> 1.1609287 | G12: KJ/KG K
E13: rango de T | F13: =B8 -> 255.50812 | G13: K
A14: T0final | B14: =B11+B12 -> 1255.5081 | C14: K
A15: R | B15: 0.287 | C15: KJ / Kg·K
A16: Cp/R para T<1000 | C16: J/(kg K)
A17: a0 | B17: 3.5839058
A18: a1 | B18: -0.000750907
A19: a2 | B19: 1.87026e-06
A20: a3 | B20: -3.91028e-10
A21: a4 | B21: -3.14052e-13
A22: Cp/R para T>1000
A23: a0 | B23: 3.0483823
A24: a1 | B24: 0.001324338
A25: a2 | B25: -4.64808e-07
A26: a3 | B26: 7.32631e-11
A27: a4 | B27: -4.15928e-15

Sheet Turbina
A1: Datos de entrada de la turbina | B1: valor | C1: unidad | E1: Primeros Parametros | F1: valor | G1: Unidad
A2: T01 | B2: =Camara_Combustion!B14 -> 1255.5081 | C2: K | E2: eta_c | F2: =(1-B25^B27)/(1-B25^(B27*(1/B8))) -> 0.91595188
A3: P01 | B3: =101*4.5 -> 454.5 | C3: Kpa | E3: Delta_T0 | F3: =(B2/F2)*(B25^(B28)-1) -> -427.14036 | G3: K
A4: cp | B4: {=(B14+B15*B2+B16*B2^{2}+B17*B2^{3}+B18*B2^{4})*B5*1000} -> 1180.4538 | C4: J/kg*K
A5: R | B5: 0.287 | C5: KJ/kg*K
A6: rho01 | B6: =B3/B5/1000/1000*B2 -> 1.9882524 | C6: Kg/m3
A7: gamma | B7: 1.32 | E7: Datos de la Figura | F7: valores | G7: unidades | H7: observación
A8: Eficiencia politropica | B8: 0.9 | E8: psi | F8: 2 | H8: turbina de impuslo
A9: \alpha_2 | B9: 74.3 | C9: ° | D9: entre 65 y 77 | E9: fi | F9: =F8/TAN(B9*PI()/180) -> 0.56217465
A10: m | B10: =Compresor!C3 -> 30 | C10: kg/s | E10: epsilon_R | F10: 105 | G10: ° | H10: figura 4
A11: rp | B11: 0.25 | E11: Eta_tt | F11: 0.895 | H11: figura 4
A12: Velocidad de Giro | B12: =Compresor!G16 -> 7197.0956 | C12: rpm | E12: cx | F12: 178.5 | G12: m/s
A13: Cp/R para T>1000 | E13: um | F13: =F12/F9 -> 317.51699 | G13: m/s | H13: fi=cx/u
A14: a0 | B14: 3.0483823
A15: a1 | B15: 0.001324338
A16: a2 | B16: -4.64808e-07
A17: a3 | B17: 7.32631e-11
A18: a4 | B18: -4.15928e-15
A19: Cp/R para T<1000 | C19: J/(kg K)
A20: a0 | B20: 3.5839058
A21: a1 | B21: -0.000750907 | F21: 0
A22: a2 | B22: 1.87026e-06
A23: a3 | B23: -3.91028e-10
A24: a4 | B24: -3.14052e-13
A25: rp | B25: 0.25
A26: gamma | B26: 1.32
A27: gamma-1/gamma | B27: =(B26-1)/B26 -> 0.24242424
A28: (gamma-1)/(gamma*eficiencia_pt) | B28: =(B26-1)/(B26*B8) -> 0.26936027
A29: (gamma*eficiencia_pt)/(gamma-1) | B29: =1/B28 -> 3.7125
B30: Parametros de la salida | M30: T01=T02
A31: Peso | B31: Etapa | C31: c2(m/s) | D31: c_teta2(m/s) | E31: w2(m/s) | F31: w_theta2(m/s) | G31: cp_max(J/kgK) | H31: cp_min(J/kgK) | I31: cp_medi(J/kgK) | J31: Delta_T0_etapa [K] | K31: T01[K] | L31: T1[K] | M31: T2[K] | N31: T03[K] | O31: P_01(Kpa) | P31: P03 (Kpa) | Q31: P03/P01 | R31: M2_rel | S31: M2_abs
A32: 1 | B32: 1 | C32: =$F$12/COS($B$9*PI()/180) -> 659.64415 | D32: =$F$12*TAN($B$9*PI()/180) -> 635.03397 | E32: =SQRT((C32*COS($B$9*PI()/180))^2+$F$13^2) -> 364.25168 | F32: =2*$F$13 -> 635.03397 | G32: =$B$5*($B$14+$B$15*K32+$B$16*K32^2+$B$17*K32^3+$B$18*K32^4)*1000 -> 1180.4538 | H32: =$B$5*($B$14+$B$15*N32+$B$16*N32^2+$B$17*N32^3+$B$18*N32^4)*1000 -> 1155.096 | I32: =(G32+H32)/2 -> 1167.7749 | J32: =K32*(2*$F$13^2/(K32*I32)) -> 172.66518 | K32: =B2 -> 1255.5081 | L32: =K32-($F$12^2/(2*G32)) -> 1242.0124 | M32: =K32-(C32^2/(2*H32)) -> 1067.1556 | N32: =K32-J32 -> 1082.8429 | O32: =B3 -> 454.5 | P32: =(O32)/((K32/N32)^($B$29)) -> 262.41623 | Q32: =P32/O32 -> 0.57737345 | R32: =E32/SQRT($B$26*1000*$B$5*M32) -> 0.57287487 | S32: =D32/SQRT($B$26*1000*$B$5*M32) -> 0.99874626
A33: 1 | B33: 2 | C33: =$F$12/COS($B$9*PI()/180) -> 659.64415 | D33: =$F$12*TAN($B$9*PI()/180) -> 635.03397 | E33: =SQRT((C33*COS($B$9*PI()/180))^2+$F$13^2) -> 364.25168 | F33: =2*$F$13 -> 635.03397 | G33: =$B$5*($B$14+$B$15*K33+$B$16*K33^2+$B$17*K33^3+$B$18*K33^4)*1000 -> 1155.096 | H33: =$B$5*($B$14+$B$15*N33+$B$16*N33^2+$B$17*N33^3+$B$18*N33^4)*1000 -> 1124.5656 | I33: =(G33+H33)/2 -> 1139.8308 | J33: =K33*(2*$F$13^2/(K33*I33)) -> 176.89825 | K33: =N32 -> 1082.8429 | L33: =K33-($F$12^2/(2*G33)) -> 1069.0509 | M33: =K33-(C33^2/(2*H33)) -> 889.37694 | N33: =K33-J33 -> 905.94468 | O33: =P32 -> 262.41623 | P33: =(O33)/((K33/N33)^($B$29)) -> 135.33384 | Q33: =P33/O33 -> 0.51572205 | R33: =E33/SQRT($B$26*1000*$B$5*M33) -> 0.62752455 | S33: =D33/SQRT($B$26*1000*$B$5*M33) -> 1.0940221
A34: 1 | B34: 3 | C34: =$F$12/COS($B$9*PI()/180) -> 659.64415 | D34: =$F$12*TAN($B$9*PI()/180) -> 635.03397 | E34: =SQRT((C34*COS($B$9*PI()/180))^2+$F$13^2) -> 364.25168 | F34: =2*$F$13 -> 635.03397 | G34: =$B$5*($B$14+$B$15*K34+$B$16*K34^2+$B$17*K34^3+$B$18*K34^4)*1000 -> 1124.5656 | H34: =$B$5*($B$14+$B$15*N34+$B$16*N34^2+$B$17*N34^3+$B$18*N34^4)*1000 -> 1087.7194 | I34: =(G34+H34)/2 -> 1106.1425 | J34: =K34*(2*$F$13^2/(K34*I34)) -> 182.2858 | K34: =N33 -> 905.94468 | L34: =K34-($F$12^2/(2*G34)) -> 891.77821 | M34: =K34-(C34^2/(2*H34)) -> 705.92509 | N34: =K34-J34 -> 723.65889 | O34: =P33 -> 135.33384 | P34: =(O34)/((K34/N34)^($B$29)) -> 58.774102 | Q34: =P34/O34 -> 0.43428978 | R34: =E34/SQRT($B$26*1000*$B$5*M34) -> 0.70435944 | S34: =D34/SQRT($B$26*1000*$B$5*M34) -> 1.2279756
A35: 1 | B35: 4 | C35: =$F$12/COS($B$9*PI()/180) -> 659.64415 | D35: =$F$12*TAN($B$9*PI()/180) -> 635.03397 | E35: =SQRT((C35*COS($B$9*PI()/180))^2+$F$13^2) -> 364.25168 | F35: =2*$F$13 -> 635.03397 | G35: =$B$5*($B$20+$B$21*K35+$B$22*K35^2+$B$23*K35^3+$B$24*K35^4)*1000 -> 1086.4711 | H35: =$B$5*($B$20+$B$21*N35+$B$22*N35^2+$B$23*N35^3+$B$24*N35^4)*1000 -> 1042.186 | I35: =(G35+H35)/2 -> 1064.3286 | J35: =K35*(2*$F$13^2/(K35*I35)) -> 189.44721 | K35: =N34 -> 723.65889 | L35: =K35-($F$12^2/(2*G35)) -> 708.9957 | M35: =K35-(C35^2/(2*H35)) -> 514.90037 | N35: =K35-J35 -> 534.21168 | O35: =P34 -> 58.774102 | P35: =(O35)/((K35/N35)^($B$29)) -> 19.045936 | Q35: =P35/O35 -> 0.32405319 | R35: =E35/SQRT($B$26*1000*$B$5*M35) -> 0.82473049 | S35: =D35/SQRT($B$26*1000*$B$5*M35) -> 1.4378297
A36: 0 | B36: 5 | C36: =$F$12/COS($B$9*PI()/180) -> 659.64415 | D36: =$F$12*TAN($B$9*PI()/180) -> 635.03397 | E36: =SQRT((C36*COS($B$9*PI()/180))^2+$F$13^2) -> 364.25168 | F36: =2*$F$13 -> 635.03397 | G36: =$B$5*($B$20+$B$21*K36+$B$22*K36^2+$B$23*K36^3+$B$24*K36^4)*1000 -> 1042.186 | H36: =$B$5*($B$20+$B$21*N36+$B$22*N36^2+$B$23*N36^3+$B$24*N36^4)*1000 -> 1011.5367 | I36: =(G36+H36)/2 -> 1026.8613 | J36: =K36*(2*$F$13^2/(K36*I36)) -> 196.3596 | K36: =N35 -> 534.21168 | L36: =K36-($F$12^2/(2*G36)) -> 518.92542 | M36: =K36-(C36^2/(2*H36)) -> 319.12783 | N36: =K36-J36 -> 337.85208 | O36: =P35 -> 19.045936 | P36: =(O36)/((K36/N36)^($B$29)) -> 3.4758729 | Q36: =P36/O36 -> 0.18249946 | R36: =E36/SQRT($B$26*1000*$B$5*M36) -> 1.0475899 | S36: =D36/SQRT($B$26*1000*$B$5*M36) -> 1.8263613
Q38: =Q32*Q34 -> 0.25074739
B39: Parametros geometricos
A40: Peso | B40: Etapa | C40: P02[Kpa] | D40: P2[Kpa] | E40: rho[k/m3] | F40: A[mm2] | G40: r_m [mm] | H40: r_tip [mm] | I40: r_hub [mm] | J40: r_tip/r_hub
A41: =A32 -> 1 | B41: =B32 -> 1 | C41: =O32 -> 454.5 | D41: =C41/(1+(($B$26-1)/2)*R32^2)^($B$26/($B$26-1)) -> 368.00286 | E41: =D41/($B$5*M32) -> 1.2015491 | F41: =$B$10/(E41*$F$12)*(1000^2) -> 139875.45 | G41: =F$13/((B$12*2*PI())/60)*1000 -> 421.28993 | H41: =SQRT(G41^2+(F41/(2*PI()))) -> 446.93072 | I41: =SQRT(G41^2-(F41/(2*PI()))) -> 393.98393 | J41: =I41/H41 -> 0.88153243
...

Sheet Presentacion de resultados
B1: Etapa | C1: P02[Kpa] | D1: P2[Kpa] | E1: rho[k/m3] | F1: A[mm2] | G1: r_m [mm] | H1: r_tip [mm] | I1: r_hub [mm] | J1: r_tip/r_hub
B2: 1 | C2: 454.5 | D2: 368.00286 | E2: 1.2015491 | F2: 139875.45 | G2: 421.28993 | H2: 446.93072 | I2: 393.98393 | J2: 0.88153243
B3: 2 | C3: 262.41623 | D3: 203.95342 | E3: 0.79903026 | F3: 210339 | G3: 421.28993 | H3: 459.30567 | I3: 379.4848 | J3: 0.82621406
B7: Etapa | C7: c2(m/s) | D7: c_teta2(m/s) | E7: w2(m/s) | F7: w_theta2(m/s) | G7: cp_max(J/kgK) | H7: cp_min(J/kgK) | I7: cp_medi(J/kgK) | J7: Delta_T0_etapa [K] | K7: T01[K] | L7: T1[K] | M7: T2[K] | N7: T03[K] | O7: P_01(Kpa) | P7: P03 (Kpa) | Q7: P03/P01 | R7: M2_rel
B8: 1 | C8: 659.64415 | D8: 635.03397 | E8: 364.25168 | F8: 635.03397 | G8: 1180.4538 | H8: 1155.096 | I8: 1167.7749 | J8: 172.66518 | K8: 1255.5081 | L8: 1242.0124 | M8: 1067.1556 | N8: 1082.8429 | O8: 454.5 | P8: 262.41623 | Q8: 0.57737345 | R8: 0.57287487
B9: 2 | C9: 659.64415 | D9: 635.03397 | E9: 364.25168 | F9: 635.03397 | G9: 1155.096 | H9: 1124.5656 | I9: 1139.8308 | J9: 176.89825 | K9: 1082.8429 | L9: 1069.0509 | M9: 889.37694 | N9: 905.94468 | O9: 262.41623 | P9: 135.33384 | Q9: 0.51572205 | R9: 0.62752455
